<?xml version="1.0"?>
<robot xmlns:xacro="http://www.ros.org/wiki/xacro" name="schunk_gripper">
	<xacro:macro name="gripper" params="parent">
		<joint name="schunk_gripper_joint" type="fixed">
			<origin xyz="0.0 0.0 0" rpy="0 0 ${pi/2}"/>
			<parent link="${parent}" />
			<child link="schunk_gripper" />
		</joint>

		<link name="schunk_gripper">
			<inertial>
				<origin xyz="1.8659E-06 -0.0089716 0.020086" rpy="0 0 0" />
				<mass value="0.19023" />
				<inertia ixx="0.00012151" ixy="-9.2983E-08" ixz="1.3019E-10" iyy="7.2672E-05" iyz="-4.6523E-07" izz="0.00019065" />
			</inertial>
			<visual>
				<origin xyz="0 0 0" rpy="0 0 0" />
				<geometry>
					<mesh filename="package://samk_description/meshes/schunk_gripper.STL" />
				</geometry>
				<material name="white">
					<color rgba="1 1 1 1" />
				</material>
			</visual>
			<collision>
				<origin xyz="0 0 0" rpy="0 0 0" />
				<geometry>
					<mesh filename="package://samk_description/meshes/schunk_gripper.STL" />
				</geometry>
			</collision>
		</link>
		<link name="finger1_link">
			<inertial>
				<origin xyz="-0.023224 4.8074E-06 0.15525" rpy="0 0 0" />
				<mass value="0.0026753" />
				<inertia ixx="3.6565E-07" ixy="-4.4111E-11" ixz="1.5685E-08" iyy="2.7762E-07" iyz="4.1901E-11" izz="9.9941E-08" />
			</inertial>
			<visual>
				<origin xyz="0 0 0" rpy="0 0 0" />
				<geometry>
					<mesh filename="package://samk_description/meshes/finger1_link.STL" />
				</geometry>
				<material name="red">
					<color rgba="1 0 0 1" />
				</material>
			</visual>
			<!-- <collision>
				<origin xyz="0 0 0" rpy="0 0 0" />
				<geometry>
					<mesh filename="package://samk_description/meshes/finger1_link.STL" />
				</geometry>
			</collision> -->
		</link>
		<joint name="finger1_joint" type="prismatic">
			<origin xyz="0 0 0" rpy="0 0 0" />
			<parent link="schunk_gripper" />
			<child link="finger1_link" />
			<axis xyz="1 0 0" />
			<limit lower="-0.006" upper="0.006" effort="35" velocity="0.02" />
		</joint>
		<link name="finger2_link">
			<inertial>
				<origin xyz="0.023225 -4.6789E-06 0.15525" rpy="0 0 0" />
				<mass value="0.0026753" />
				<inertia ixx="3.6565E-07" ixy="-4.4111E-11" ixz="-1.5685E-08" iyy="2.7762E-07" iyz="-4.1901E-11" izz="9.9939E-08" />
			</inertial>
			<visual>
				<origin xyz="0 0 0" rpy="0 0 0" />
				<geometry>
					<mesh filename="package://samk_description/meshes/finger2_link.STL" />
				</geometry>
				<material name="teal">
					<color rgba="0 1 1 1" />
				</material>
			</visual>
			<!-- <collision>
				<origin xyz="0 0 0" rpy="0 0 0" />
				<geometry>
					<mesh filename="package://samk_description/meshes/finger2_link.STL" />
				</geometry>
			</collision> -->
		</link>
		<joint name="finger2_joint" type="prismatic">
			<origin xyz="0 0 0" rpy="0 0 0" />
			<parent link="schunk_gripper" />
			<child link="finger2_link" />
			<axis xyz="-1 0 0" />
			<limit lower="-0.006" upper="0.006" effort="35" velocity="0.02" />
			<mimic joint="finger1_joint" multiplier="1" offset="0" />
		</joint>

		<transmission name="finger1_joint_trans">
			<type>transmission_interface/SimpleTransmission</type>
			<joint name="finger1_joint">
				<hardwareInterface>hardware_interface/PositionJointInterface</hardwareInterface>
			</joint>
			<actuator name="finger1_joint_motor">
				<mechanicalReduction>1</mechanicalReduction>
			</actuator>
		</transmission>

		<transmission name="finger2_joint_trans">
			<type>transmission_interface/SimpleTransmission</type>
			<joint name="finger2_joint">
				<hardwareInterface>hardware_interface/PositionJointInterface</hardwareInterface>
			</joint>
			<actuator name="finger2_joint_motor">
				<mechanicalReduction>1</mechanicalReduction>
			</actuator>
		</transmission>

		<gazebo>
			<plugin filename="libroboticsgroup_gazebo_mimic_joint_plugin.so" name="mimic_joints">
				<joint>finger1_joint</joint>
				<mimicJoint>finger2_joint</mimicJoint>
				<multiplier>1.0</multiplier>
			</plugin>
		</gazebo>

		<gazebo reference="finger1_link">
			<material>Gazebo/Red</material>
			<mu1>1.0</mu1>
			<mu2>1.0</mu2>
		</gazebo>

		<gazebo reference="finger2_link">
			<material>Gazebo/Turquoise</material>
			<mu1>1.0</mu1>
			<mu2>1.0</mu2>
		</gazebo>

		<link name="gripper_eef">
		</link>
		<joint name="gripper_eef_joint" type="fixed">
			<parent link="schunk_gripper"/>
			<child link="gripper_eef"/>
			<origin xyz="0.0 0.0 0.160" rpy="0.0 0.0 0.0"/>
		</joint>

	</xacro:macro>

</robot>